from unittest.mock import patch

from django.core.management import call_command
from django.db.utils import OperationalError
from django.test import TestCase


class CommandTests(TestCase):

    def test_wait_for_db_ready(self):
        """
        Tests the wait for db manage command
        when the database is already available
        """

        with patch('django.db.utils.ConnectionHandler.__getitem__') as gi:
            gi.return_value = True
            call_command('wait_for_db')
            self.assertEqual(gi.call_count, 1)

    @patch('time.sleep', return_value=True)
    def test_wait_for_db(self, ts):
        """Test waiting for db"""

        with patch('django.db.utils.ConnectionHandler.__getitem__') as gi:
            # This makes the database connection fail 5 times throwing an
            # OperationalError exception to later succeed on the 6th attempt
            gi.side_effect = [OperationalError] * 5 + [True]
            call_command('wait_for_db')
            self.assertEqual(gi.call_count, 6)
